Loading required package: Rcpp
Read in 293, output 0 (0%) filtered sequences.
Error in sapply(match.fwd, end) + 1 : 
  non-numeric argument to binary operator
3: removePrimers(unfilts, nop, primer, dada2:::rc(primerR), max.mismatch = maxMismatch, 
       allow.indels = indels, orient = TRUE, verbose = TRUE)
2: withCallingHandlers(expr, warning = function(w) if (inherits(w, 
       classes)) tryInvokeRestart("muffleWarning"))
1: suppressWarnings(removePrimers(unfilts, nop, primer, dada2:::rc(primerR), 
       max.mismatch = maxMismatch, allow.indels = indels, orient = TRUE, 
       verbose = TRUE))
Traceback (most recent call last):
  File "/home/lubo/miniconda3/envs/qiime2-2022.11/lib/python3.8/site-packages/q2_dada2/_denoise.py", line 440, in denoise_ccs
    run_commands([cmd])
  File "/home/lubo/miniconda3/envs/qiime2-2022.11/lib/python3.8/site-packages/q2_dada2/_denoise.py", line 36, in run_commands
    subprocess.run(cmd, check=True)
  File "/home/lubo/miniconda3/envs/qiime2-2022.11/lib/python3.8/subprocess.py", line 516, in run
    raise CalledProcessError(retcode, process.args,
subprocess.CalledProcessError: Command '['run_dada.R', '--input_directory', '/tmp/qiime2/lubo/data/fbdcd241-df43-48b7-95da-d81d2139161a/data', '--output_path', '/tmp/tmpo9hgtru2/output.tsv.biom', '--output_track', '/tmp/tmpo9hgtru2/track.tsv', '--removed_primer_directory', '/tmp/tmpo9hgtru2/nop', '--filtered_directory', '/tmp/tmpo9hgtru2/filt', '--forward_primer', 'CTGGTTGATYCTGCCAGT', '--reverse_primer', 'GACGAGGCATTTGGCTACCTT', '--max_mismatch', '2', '--indels', 'False', '--truncation_length', '0', '--trim_left', '0', '--max_expected_errors', '2.0', '--truncation_quality_score', '2', '--min_length', '3000', '--max_length', '6000', '--pooling_method', 'independent', '--chimera_method', 'consensus', '--min_parental_fold', '3.5', '--allow_one_off', 'False', '--num_threads', '12', '--learn_min_reads', '100000', '--homopolymer_gap_penalty', 'NULL', '--band_size', '32']' returned non-zero exit status 1.

During handling of the above exception, another exception occurred:

Traceback (most recent call last):
  File "/home/lubo/miniconda3/envs/qiime2-2022.11/lib/python3.8/site-packages/q2cli/commands.py", line 352, in __call__
    results = action(**arguments)
  File "<decorator-gen-262>", line 2, in denoise_ccs
  File "/home/lubo/miniconda3/envs/qiime2-2022.11/lib/python3.8/site-packages/qiime2/sdk/action.py", line 234, in bound_callable
    outputs = self._callable_executor_(scope, callable_args,
  File "/home/lubo/miniconda3/envs/qiime2-2022.11/lib/python3.8/site-packages/qiime2/sdk/action.py", line 381, in _callable_executor_
    output_views = self._callable(**view_args)
  File "/home/lubo/miniconda3/envs/qiime2-2022.11/lib/python3.8/site-packages/q2_dada2/_denoise.py", line 449, in denoise_ccs
    raise Exception("An error was encountered while running DADA2"
Exception: An error was encountered while running DADA2 in R (return code 1), please inspect stdout and stderr to learn more.

Plugin error from dada2:

  An error was encountered while running DADA2 in R (return code 1), please inspect stdout and stderr to learn more.

See above for debug info.
